<?xml version="1.0"?>
<robot name="amr" xmlns:xacro="http://www.ros.org/wiki/xacro"> 

        <!-- wheel params -->
        <xacro:property name="radius" value="0.1"/>
        <xacro:property name="height_w" value="0.06"/>
        <xacro:property name="mass_w" value="1"/>

        <!-- rialzo params -->
        <xacro:property name="height_r" value="0.072"/>
        <xacro:property name="width_r" value="0.925"/>
        <xacro:property name="depth_r" value="0.8862"/>
        <xacro:property name="mass_r" value="1"/>

        <!--body params-->
        <xacro:property name="height_b" value="0.2579"/>
        <xacro:property name="width_b" value="1.3008"/>
        <xacro:property name="depth_b" value="0.9008"/>
        <xacro:property name="mass_b" value="10"/>

        <link name="left_wheel">
            <inertial>
                <origin xyz="0 -0.37 -0.1" rpy="0 0 0"/>
                <mass value="${mass_w}"/>
                <inertia ixx="${mass_w*(3*radius*radius+height_w*height_w)/12}" ixy="0" ixz="0" iyy="${mass_w*(3*radius*radius+height_w*height_w)/12}" iyz="0" izz="${mass_w*radius*radius/2}"/>
            </inertial>
            <visual>
                <geometry>
                    <mesh filename="package://amr/visual/left_wheel.dae" scale="0.001 0.001 0.001"/>
                </geometry>
                <origin xyz="0 -0.37 -0.1" rpy="0 0 0"/>
            </visual>
            <collision>
                <geometry>
                    <mesh filename="package://amr/collision/left_wheel.stl" scale="0.001 0.001 0.001"/>
                </geometry>
                <surface>
                    <friction>
                        <ode>
                            <mu>0.5</mu>
                            <mu2>0.5</mu2> 
                        </ode>
                    </friction>
                </surface>
                <origin xyz="0 -0.37 -0.1" rpy="0 0 0"/>
            </collision>
        </link>

        <link name="right_wheel">
            <inertial>     
                <origin xyz="0 0.37 -0.1" rpy="0 0 0"/>
                <mass value="${mass_w}"/>
                <inertia ixx="${mass_w*(3*radius*radius+height_w*height_w)/12}" ixy="0" ixz="0" iyy="${mass_w*(3*radius*radius+height_w*height_w)/12}" iyz="0" izz="${mass_w*radius*radius/2}"/>
            </inertial>
            <visual>
                <geometry>
                    <mesh filename="package://amr/visual/right_wheel.dae" scale="0.001 0.001 0.001"/>
                </geometry>
                <origin xyz="0 0.37 -0.1" rpy="0 0 0"/>
            </visual>
            <collision>
                <geometry>
                    <mesh filename="package://amr/collision/right_wheel.stl" scale="0.001 0.001 0.001"/>
                </geometry>
                <surface>
                    <friction>
                        <ode>
                            <mu>0.5</mu>
                            <mu2>0.5</mu2> 
                        </ode> 
                    </friction>
                </surface>
                <origin xyz="0 0.37 -0.1" rpy="0 0 0"/>
            </collision>
        </link>

        <link name="amr_body">
            <inertial>
                <origin xyz="0 0 0" rpy="0 0 0"/>
                <mass value="${mass_b}"/>
                <inertia ixx="${mass_b*(height_b*height_b+depth_b*depth_b)/12}" ixy="0" ixz="0" iyy="${mass_b*(height_b*height_b+width_b*width_b)/12}" iyz="0" izz="${mass_b*(width_b*width_b+depth_b*depth_b)/12}"/>
            </inertial>
            <visual>
                <geometry>
                    <mesh filename="package://amr/visual/amr_body.dae" scale="0.001 0.001 0.001"/>
                </geometry>
                <origin xyz="0 0 0" rpy="0 0 0"/>
            </visual>
            <collision>
                <geometry>
                    <mesh filename="package://amr/collision/amr_body_simp.stl" scale="0.001 0.001 0.001"/>
                </geometry>
                <origin xyz="0 0 0" rpy="0 0 0"/>
            </collision>
        </link>

        <link name="amr_rialzo">
            <inertial>
                <origin xyz="0 0 0" rpy="0 0 0"/>
                <mass value="${mass_r}"/>
                <inertia ixx="${mass_r*(height_r*height_r+depth_r*depth_r)/12}" ixy="0" ixz="0" iyy="${mass_r*(height_r*height_r+width_r*width_r)/12}" iyz="0" izz="${mass_r*(width_r*width_r+depth_r*depth_r)/12}"/>
            </inertial>
            <visual>
                <geometry>
                    <mesh filename="package://amr/visual/amr_rialzo.dae" scale="0.001 0.001 0.001"/>
                </geometry>
                <origin xyz="0 0 0" rpy="0 0 0"/>
            </visual>
            <collision>
                <geometry>
                    <mesh filename="package://amr/collision/amr_rialzo_simp.stl" scale="0.001 0.001 0.001"/>
                </geometry>
                <origin xyz="0 0 0" rpy="0 0 0"/>
            </collision>
        </link>

        <link name="laser_front">
            <inertial>
            <origin xyz="0 0 0" rpy="0 0 0"/>
                <mass value="0.005"/>
                <inertia ixx="0.0005" ixy="0" ixz="0" iyy="0.0005" iyz="0" izz="0.0005"/>
            </inertial>
            <!-- <visual>
                <geometry>
                    <mesh filename="package://amr/visual/laser_front.dae" scale="0.001 0.001 0.001"/>
                </geometry>
                <origin xyz="-0.57 -0.37 -0.17" rpy="0 0 0"/>
            </visual>
            <collision>
                <geometry>
                    <mesh filename="package://amr/collision/laser_front.stl" scale="0.001 0.001 0.001"/>
                </geometry>
                <origin xyz="-0.57 -0.37 -0.17" rpy="0 0 0"/>
            </collision> -->
        </link>

        <link name="laser_back">
            <inertial>
            <origin xyz="0 0 0" rpy="0 0 0"/>
                <mass value="0.005"/>
                <inertia ixx="0.0005" ixy="0" ixz="0" iyy="0.0005" iyz="0" izz="0.0005"/>
            </inertial>
            <!-- <visual>
                <geometry>
                    <mesh filename="package://amr/visual/laser_back.dae" scale="0.001 0.001 0.001"/>
                </geometry>
                <origin xyz="0.37 0.57 -0.17" rpy="0 0 0"/>
            </visual>
            <collision>
                <geometry>
                    <mesh filename="package://amr/collision/laser_back.stl" scale="0.001 0.001 0.001"/>
                </geometry>
                <origin xyz="0.37 0.57 -0.17" rpy="0 0 0"/>
            </collision> -->
        </link>

        <link name="base_footprint" />

        <joint name="laser_front_joint" type="fixed">
            <parent link="amr_body"/>
            <child link="laser_front"/>
            <origin xyz="0.57 0.45 0.17" rpy="0 0 0"/>
        </joint>

        <joint name="laser_back_joint" type="fixed">
            <parent link="amr_body"/>
            <child link="laser_back"/>
            <origin xyz="-0.57 -0.45 0.17" rpy="0 0 0"/>
        </joint>


        <joint name="left_wheel_joint" type="continuous">
            <parent link="amr_body"/>
            <child link="left_wheel"/>
            <origin xyz="0 0.37 0.1" rpy="0 0 0"/>
            <limit effort="100" velocity="1.5"/>
            <axis xyz="0 1 0"/>
            <dynamics damping="0.5" friction="0.1" />
        </joint>

        <joint name="right_wheel_joint" type="continuous">
            <parent link="amr_body"/>
            <child link="right_wheel"/>
            <origin xyz="0 -0.37 0.1" rpy="0 0 0"/>
            <limit effort="100" velocity="1.5"/>
            <axis xyz="0 1 0"/>
            <dynamics damping="0.5" friction="0.1" />
        </joint>

        <joint name="rialzo_joint" type="prismatic">
            <parent link="amr_body"/>
            <child link="amr_rialzo"/>
            <origin xyz="0 0 0" rpy="0 0 0"/>
            <limit lower="0" upper="0.06" velocity="0.02" effort="10"/>
            <axis xyz="0 0 1"/>
            <dynamics damping="0.1" friction="0.1" />
        </joint>

        <joint name="footprint_joint" type="fixed">
            <parent link="amr_body"/>
            <child link="base_footprint"/>
            <origin xyz="0 0 0" rpy="0 0 0"/>
        </joint>

        <transmission name="trans_rialzo_joint" >
            <type>transmission_interface/SimpleTransmission</type>
            <joint name = "rialzo_joint" >
                <hardwareInterface>hardware_interface/EffortJointInterface</hardwareInterface>
            </joint>
            <actuator name="motor_rialzo_joint" >
                <hardwareInterface>hardware_interface/EffortJointInterface</hardwareInterface>
                <mechanicalReduction>50</mechanicalReduction>
            </actuator>
        </transmission>

        <transmission name="trans_left_wheel_joint" >
            <type>transmission_interface/SimpleTransmission</type>
            <joint name = "left_wheel_joint" >
                <hardwareInterface>hardware_interface/VelocityJointInterface</hardwareInterface>
            </joint>
            <actuator name="motor_left_wheel_joint" >
                <hardwareInterface>hardware_interface/VelocityJointInterface</hardwareInterface>
                <mechanicalReduction>10</mechanicalReduction>
            </actuator>
        </transmission>

        <transmission name="trans_right_wheel_joint" >
            <type>transmission_interface/SimpleTransmission</type>
            <joint name = "right_wheel_joint" >
                <hardwareInterface>hardware_interface/VelocityJointInterface</hardwareInterface>
            </joint>
            <actuator name="motor_right_wheel_joint" >
                <hardwareInterface>hardware_interface/VelocityJointInterface</hardwareInterface>
                <mechanicalReduction>10</mechanicalReduction>
            </actuator>
        </transmission>

        <gazebo>
            <plugin name="gazebo_ros_control" filename="libgazebo_ros_control.so">
                <robotNamespace>amr</robotNamespace>
                  <!-- <robotParam>robot_description</robotParam> -->
                <controlPeriod>0.001</controlPeriod>
                <robotSimType>gazebo_ros_control/DefaultRobotHWSim</robotSimType>
                <legacyModeNS>false</legacyModeNS>
            </plugin>
            <plugin name='diff_drive' filename='libgazebo_ros_diff_drive.so'>
                <!-- Wheel Information -->
                <leftJoint>left_wheel_joint</leftJoint>
                <rightJoint>right_wheel_joint</rightJoint>
                <wheelSeparation>0.73</wheelSeparation>
                <wheelDiameter>0.2</wheelDiameter>
                <!-- Limits -->
                <wheelTorque>10</wheelTorque>
                <wheelAcceleration>0.6</wheelAcceleration>
                <!-- Output -->
                <odometryFrame>odom</odometryFrame>
                <robotBaseFrame>base_footprint</robotBaseFrame>
                <publishOdomTF>true</publishOdomTF>
                <publishWheelTF>true</publishWheelTF>
                <publishOdom>true</publishOdom>
                <alwaysOn>true</alwaysOn>
                <updateRate>10</updateRate>
                <legacyMode>false</legacyMode>
                <commandTopic>cmd_vel</commandTopic>
                <odometryTopic>odom</odometryTopic>
                <publishWheelJointState>true</publishWheelJointState>
                <rosDebugLevel>na</rosDebugLevel>
                <odometrySource>encoder</odometrySource>
                <publishTf>1</publishTf>
            </plugin>
        </gazebo>

        <gazebo reference="laser_front">
            <sensor name="laser_front_sensor" type="ray">
                <visualize>true</visualize>
                <update_rate>1</update_rate>
                <ray> 
                   <scan>
                        <horizontal>
                            <samples>270</samples>
                            <min_angle>-1.570796</min_angle>
                            <max_angle>3.141592</max_angle>
                        </horizontal>
                    </scan>
                    <range>
                        <min>0</min>
                        <max>4</max>
                        <resolution>0.01</resolution>
                    </range> 
                </ray>
                <plugin name="laser_front_controller" filename="libgazebo_ros_laser.so">
                    <ros>
                        <argument>~/out:=scan</argument>
                    </ros>
                    <topicName>/amr/laser_front/scan</topicName>
                    <output_type>sensor_msgs/LaserScan</output_type>
                    <frameName>laser_front</frameName>
                </plugin>
            </sensor>
        </gazebo>

        <gazebo reference="laser_back">
            <sensor name="laser_back_sensor" type="ray">
                <visualize>true</visualize>
                <update_rate>1</update_rate>
                <ray> 
                   <scan>
                        <horizontal>
                            <samples>270</samples>
                            <min_angle>-3.141592</min_angle>
                            <max_angle>3.141592</max_angle>
                        </horizontal>
                    </scan>
                    <range>
                        <min>0</min>
                        <max>4</max>
                        <resolution>0.01</resolution>
                    </range> 
                </ray>
                <plugin name="laser_back_controller" filename="libgazebo_ros_laser.so">
                    <ros>
                        <argument>~/out:=scan</argument>
                    </ros>
                    <topicName>/amr/laser_back/scan</topicName>
                    <output_type>sensor_msgs/LaserScan</output_type>
                    <frameName>laser_back</frameName>
                </plugin>
            </sensor>
        </gazebo>

        <gazebo>
            <plugin name="joint_state_publisher" filename="libgazebo_ros_joint_state_publisher.so">
                <jointName>rialzo_joint</jointName>
                <updateRate>100</updateRate>
            </plugin>
        </gazebo>


</robot>
